<mujoco model="hopper">
  <compiler angle="degree" coordinate="global" inertiafromgeom="true"/>
  <default>
    <joint armature="1" damping="1" limited="true"/>
    <geom conaffinity="1" condim="1" contype="1" margin="0.001" rgba=".98 .54 .56 1." solimp=".8 .8 .01" solref=".02 1"/>
    <motor ctrllimited="true" ctrlrange="-.4 .4"/>
  </default>
  <option integrator="RK4" timestep="0.002"/>
  <visual>
    <headlight ambient=".1 .1 .1" diffuse=".6 .6 .6" specular="0.3 0.3 0.3"/>
    <map znear=".01"/>
    <quality shadowsize="2048"/>
  </visual>
  <worldbody>
    <light cutoff="100" diffuse="1 1 1" dir="-0 0 -1.3" directional="true" exponent="1" pos="0 0 1.3" specular=".1 .1 .1"/>
    <geom name='floor1' material="grid_new" pos='17 0 -1.5' type='hfield' conaffinity='1' rgba='0.8 0.9 0.8 1' condim='3' hfield="floor"/>
    <geom name='floor2' material="grid_new" pos='49 0 -1.5' type='hfield' conaffinity='1' rgba='0.8 0.9 0.8 1' condim='3' hfield="floor"/>
    <body name="0" pos="0 0 1.25">
      <camera name="track" mode="trackcom" pos="0 -3 1" xyaxes="1 0 0 0 0 1"/>
      <joint armature="0" axis="1 0 0" damping="0" limited="false" name="rootx" pos="0 0 0" stiffness="0" type="slide"/>
      <joint armature="0" axis="0 0 1" damping="0" limited="false" name="rootz" pos="0 0 0" ref="1.25" stiffness="0" type="slide"/>
      <joint armature="0" axis="0 1 0" damping="0" limited="false" name="0_joint" pos="0 0 1.25" stiffness="0" type="hinge"/>
      <geom friction="0.9" fromto="-0 0 1.45 0 0 1.05" size="0.05" type="capsule"/>
      <body name="1" pos="0 0 1.05">
        <joint axis="0 -1 0" name="1_joint" pos="0 0 1.05" range="-360 360" type="hinge"/>
        <geom friction="2.0" fromto="0 0 1.05 0 0 0.6" size="0.05" type="capsule"/>
      </body>
    </body>
  </worldbody>
  <actuator>
    <motor ctrllimited="true" ctrlrange="-1.0 1.0" gear="200" joint="1_joint" name="1_joint"/>
  </actuator>
  <asset>
    <texture type="skybox" builtin="gradient" rgb1=".4 .5 .6" rgb2="0 0 0" width="100" height="100"/>
    <texture builtin="flat" height="1278" mark="cross" markrgb="1 1 1" name="texgeom" random="0.01" rgb1="0.8 0.6 0.4" rgb2="0.8 0.6 0.4" type="cube" width="127"/>
    <texture builtin="checker" height="100" name="texplane" rgb1="0 0 0" rgb2="0.8 0.8 0.8" type="2d" width="100"/>
    <material name="MatPlane" reflectance="0.5" shininess="1" specular="1" texrepeat="60 60" texture="texplane"/>
    <material name="geom" texture="texgeom" texuniform="true"/>
    <hfield name="floor" size = "32 32 2 0.1" file="/tmp/mujoco_terrains/gap_terrain.png"/>
    <texture name="grid_new" type="2d" builtin="checker" rgb1=".1 .3 .2" rgb2=".2 .4 .3" width="1000" height="1000" mark="none" markrgb=".8 .6 .4"/>
    <material name="grid_new" texture="grid_new" texrepeat="0.0 0.2" texuniform="true" reflectance=".2"/>
  </asset>
</mujoco>
